<?xml version="1.0"?>
<robot name="sliding_box">

  <!-- 地面 -->
  <link name="ground">
    <visual>
      <geometry>
        <plane size="10 10"/>
      </geometry>
      <material name="ground_material">
        <color rgba="0.5 0.5 0.5 1.0"/>
      </material>
    </visual>
    <collision>
      <geometry>
        <plane size="10 10"/>
      </geometry>
    </collision>
  </link>

  <!-- 滑动的盒子 -->
  <link name="box">
    <visual>
        <geometry>
            <box size="0.5 0.2 0.1" />
        </geometry>
        <origin xyz="0 0 0" rpy="0 0 0" />
        <material name="blue">
            <color rgba="0 0 1.0 0.5" />
        </material>
    </visual>
    <collision>
      <geometry>
        <box size="0.5 0.2 0.1"/>
      </geometry>
    </collision>
    <inertial>
      <mass value="1.0"/>
      <inertia ixx="0.01" ixy="0.0" ixz="0.0" iyy="0.01" iyz="0.0" izz="0.01"/>
    </inertial>
  </link>

    <!-- 滑动关节 -->
  <joint name="slide_joint" type="prismatic">
    <parent link="ground"/>
    <child link="box"/>
    <origin xyz="0 0 0.05" rpy="0 0 0"/>
    <axis xyz="1 0 0"/> <!-- 沿 x 方向滑动 -->
    <limit lower="-5.0" upper="5.0" effort="100" velocity="1.0"/> <!-- 限制滑动范围 -->
  </joint>

 <!-- ganzi -->
    <link name="pole">
    <inertial>
        <mass value="0.2"/>
        <inertia ixx="0.002" ixy="0.0" ixz="0.0" iyy="0.00067" iyz="0.0" izz="0.002"/>
    </inertial>
    <visual>
      <geometry>
        <cylinder radius="0.02" length="0.6"/>
      </geometry>
      <origin xyz="0 0 0.3" rpy="0 0 0" />
      <material name="green">
        <color rgba="0 1 0 1"/>
      </material>
    </visual>
    <collision>
      <geometry>
        <cylinder radius="0.02" length="0.6"/>
      </geometry>
    </collision>
    </link>

    <!-- XUANZHUAN关节 -->
    <joint name="pole2box" type="continuous">
        <parent link="box"/>
        <child link="pole" />
        <!-- 需要计算两个 link 的物理中心之间的偏移量 -->
        <origin xyz="0 0 0.05" rpy="0 0 0" />
        <axis xyz="0 1 0" />
    </joint>

</robot>